2022-11-17 19:31:46,018 : num_point: 2048
2022-11-17 19:31:46,019 : emb_dim: 128
2022-11-17 19:31:46,019 : h5_file: ../../data/obj_models/ShapeNetCore_2048.h5
2022-11-17 19:31:46,019 : batch_size: 256
2022-11-17 19:31:46,020 : num_workers: 10
2022-11-17 19:31:46,020 : gpu: 0
2022-11-17 19:31:46,021 : lr: 0.0001
2022-11-17 19:31:46,021 : start_epoch: 1
2022-11-17 19:31:46,021 : max_epoch: 50
2022-11-17 19:31:46,021 : resume_model:
2022-11-17 19:31:46,021 : result_dir: results/ae_2048
2022-11-17 19:31:46,022 : repeat_epoch: 30
2022-11-17 19:31:46,022 : decay_step: 5000
2022-11-17 19:31:46,022 : decay_rate: [1.0, 0.6, 0.3, 0.1]
Traceback (most recent call last):
  File "D:\projects\python\CenterSnap\external\shape_pretraining\dataset\shape_dataset.py", line 13, in __init__
    self.length = f[self.mode].attrs['len']
  File "h5py\_objects.pyx", line 54, in h5py._objects.with_phil.wrapper
  File "h5py\_objects.pyx", line 55, in h5py._objects.with_phil.wrapper
  File "D:\projects\python\work\CenterSnap\env\lib\site-packages\h5py\_hl\group.py", line 328, in __getitem__
    oid = h5o.open(self.id, self._e(name), lapl=self._lapl)
  File "h5py\_objects.pyx", line 54, in h5py._objects.with_phil.wrapper
  File "h5py\_objects.pyx", line 55, in h5py._objects.with_phil.wrapper
  File "h5py\h5o.pyx", line 190, in h5py.h5o.open
KeyError: "Unable to open object (object 'val' doesn't exist)"